<?xml version="1.0" ?>
<!-- =================================================================================== -->
<!-- |    This document was autogenerated by xacro from invpend.xacro                  | -->
<!-- |    EDITING THIS FILE BY HAND IS NOT RECOMMENDED                                 | -->
<!-- =================================================================================== -->
<!-- Revolute-Revolute Manipulator -->
<robot name="invpend">
  <!-- pole radius -->
  <!-- ros_control plugin -->
  <gazebo>
    <plugin filename="libgazebo_ros_control.so" name="gazebo_ros_control">
      <robotNamespace>/invpend</robotNamespace>
      <robotSimType>gazebo_ros_control/DefaultRobotHWSim</robotSimType>
    </plugin>
  </gazebo>
  <!-- Slider Link -->
  <gazebo reference="slidebar">
    <material>Gazebo/Black</material>
  </gazebo>
  <!-- Cart Link -->
  <gazebo reference="cart">
    <material>Gazebo/Blue</material>
  </gazebo>
  <!-- Pole Link -->
  <gazebo reference="pole">
    <material>Gazebo/Orange</material>
  </gazebo>
  <material name="black">
    <color rgba="0.0 0.0 0.0 1.0"/>
  </material>
  <material name="blue">
    <color rgba="0.0 0.0 0.8 1.0"/>
  </material>
  <material name="green">
    <color rgba="0.0 0.8 0.0 1.0"/>
  </material>
  <material name="grey">
    <color rgba="0.2 0.2 0.2 1.0"/>
  </material>
  <material name="orange">
    <color rgba="1.0 0.4 0.03 1.0"/>
  </material>
  <material name="brown">
    <color rgba="0.87 0.81 0.76 1.0"/>
  </material>
  <material name="red">
    <color rgba="0.8 0.0 0.0 1.0"/>
  </material>
  <material name="white">
    <color rgba="1.0 1.0 1.0 1.0"/>
  </material>
  <!-- Used for fixing robot to Gazebo 'base_link' -->
  <link name="world"/>
  <joint name="fixed" type="fixed">
    <parent link="world"/>
    <child link="slidebar"/>
    <origin xyz="0 0 1"/>
  </joint>
  <!-- Slider Link -->
  <link name="slidebar">
    <visual>
      <origin rpy="0 0 0" xyz="0 0 0"/>
      <geometry>
        <box size="5 0.01 0.01"/>
      </geometry>
      <material name="black"/>
    </visual>
    <inertial>
      <origin rpy="0 0 0" xyz="0 0 0"/>
      <mass value="100"/>
      <inertia ixx="208.33333333333334" ixy="0.0" ixz="0.0" iyy="0.0" iyz="0.0" izz="208.33333333333334"/>
    </inertial>
  </link>
  <joint name="slider_to_cart" type="prismatic">
    <parent link="slidebar"/>
    <child link="cart"/>
    <origin rpy="0 0 0" xyz="0 0 0"/>
    <axis xyz="1 0 0"/>
    <limit effort="100.0" lower="-2.5" upper="2.5" velocity="1000"/>
    <!--dynamics damping="0.0001"/-->
  </joint>
  <!-- Cart Link -->
  <link name="cart">
    <collision>
      <origin rpy="0 0 0" xyz="0 0 0"/>
      <geometry>
        <box size="0.25 0.25 0.125"/>
      </geometry>
    </collision>
    <visual>
      <origin rpy="0 0 0" xyz="0 0 0"/>
      <geometry>
        <box size="0.25 0.25 0.125"/>
      </geometry>
      <material name="blue"/>
    </visual>
    <inertial>
      <origin rpy="0 0 0" xyz="0 0 0"/>
      <mass value="20.0"/>
      <inertia ixx="0.13020833333333334" ixy="0.0" ixz="0.0" iyy="0.20833333333333334" iyz="0.0" izz="0.13020833333333334"/>
    </inertial>
  </link>
  <joint name="cart_to_pole" type="revolute">
    <parent link="cart"/>
    <child link="pole"/>
    <origin rpy="0 0 0" xyz="0 -0.14750000000000002 0.03125"/>
    <axis xyz="0 1 0"/>
    <!-- <limit effort="1000.0" lower="-3.141592653589793/2" upper="3.141592653589793/2" velocity="1000.0"/> -->
    <limit effort="1000.0" lower="-6.28" upper="6.28" velocity="1000.0"/>
  </joint>
  <!-- Pole Link -->
  <link name="pole">
    <collision>
      <origin rpy="0 0 0" xyz="0 0 0.25"/>
      <geometry>
        <box size="0.025 0.025 0.5"/>
      </geometry>
    </collision>
    <visual>
      <origin rpy="0 0 0" xyz="0 0 0.25"/>
      <geometry>
        <box size="0.025 0.025 0.5"/>
      </geometry>
      <material name="orange"/>
    </visual>
    <inertial>
      <origin rpy="0 0 0" xyz="0 0 0.25"/>
      <mass value="2.0"/>
      <inertia ixx="0.16666666666666666" ixy="0.0" ixz="0.0" iyy="0.0" iyz="0.0" izz="0.16666666666666666"/>
    </inertial>
  </link>
  <transmission name="tran1">
    <type>transmission_interface/SimpleTransmission</type>
    <joint name="slider_to_cart">
      <hardwareInterface>hardware_interface/EffortJointInterface</hardwareInterface>
    </joint>
    <actuator name="motor">
      <hardwareInterface>hardware_interface/EffortJointInterface</hardwareInterface>
      <mechanicalReduction>1</mechanicalReduction>
    </actuator>
  </transmission>
  <transmission name="tran2">
    <type>transmission_interface/SimpleTransmission</type>
    <joint name="cart_to_pole">
      <hardwareInterface>hardware_interface/EffortJointInterface</hardwareInterface>
    </joint>
    <actuator name="encoder">
      <hardwareInterface>hardware_interface/EffortJointInterface</hardwareInterface>
      <mechanicalReduction>1</mechanicalReduction>
    </actuator>
  </transmission>
</robot>

